Traceback (most recent call last):
  File "C:\Users\tbeucler\.conda\envs\JB\lib\site-packages\jupyter_cache\executors\utils.py", line 58, in single_nb_execution
    executenb(
  File "C:\Users\tbeucler\.conda\envs\JB\lib\site-packages\nbclient\client.py", line 1305, in execute
    return NotebookClient(nb=nb, resources=resources, km=km, **kwargs).execute()
  File "C:\Users\tbeucler\.conda\envs\JB\lib\site-packages\jupyter_core\utils\__init__.py", line 166, in wrapped
    return loop.run_until_complete(inner)
  File "C:\Users\tbeucler\.conda\envs\JB\lib\asyncio\base_events.py", line 647, in run_until_complete
    return future.result()
  File "C:\Users\tbeucler\.conda\envs\JB\lib\site-packages\nbclient\client.py", line 705, in async_execute
    await self.async_execute_cell(
  File "C:\Users\tbeucler\.conda\envs\JB\lib\site-packages\nbclient\client.py", line 1058, in async_execute_cell
    await self._check_raise_for_error(cell, cell_index, exec_reply)
  File "C:\Users\tbeucler\.conda\envs\JB\lib\site-packages\nbclient\client.py", line 914, in _check_raise_for_error
    raise CellExecutionError.from_cell_and_msg(cell, exec_reply_content)
nbclient.exceptions.CellExecutionError: An error occurred while executing the following cell:
------------------
# Q1a: Use pandas to import the dataset
__ = pd.__(_,_)
# Q1b: Display the first rows of the data with pandas
__.__()
------------------


[1;31m---------------------------------------------------------------------------[0m
[1;31mAttributeError[0m                            Traceback (most recent call last)
Cell [1;32mIn[3], line 2[0m
[0;32m      1[0m [38;5;66;03m# Q1a: Use pandas to import the dataset[39;00m
[1;32m----> 2[0m __ [38;5;241m=[39m [43mpd[49m[38;5;241;43m.[39;49m[43m__[49m(_,_)
[0;32m      3[0m [38;5;66;03m# Q1b: Display the first rows of the data with pandas[39;00m
[0;32m      4[0m __[38;5;241m.[39m__()

[1;31mAttributeError[0m: module 'pandas' has no attribute '__'

